<?xml version="1.0" ?>
<mujoco model="default stage">
  <compiler angle="radian" autolimits="true"/>
  <statistic center="0.2 0 0.4" extent=".65"/>
  <visual>
    <headlight diffuse="0.6 0.6 0.6" ambient="0.3 0.3 0.3" specular="0 0 0"/>
    <rgba haze="0.15 0.25 0.35 1"/>
    <global azimuth="150" elevation="-20"/>
  </visual>
  <asset>
    <texture type="skybox" builtin="gradient" rgb1="0.3 0.5 0.7" rgb2="0 0 0" width="512" height="3072"/>
    <texture type="2d" name="groundplane" builtin="checker" mark="edge" rgb1="0.2 0.3 0.4" rgb2="0.1 0.2 0.3" markrgb="0.8 0.8 0.8" width="300" height="300"/>
    <material name="groundplane" texture="groundplane" texuniform="true" texrepeat="5 5" reflectance="0.2"/>
    <material class="ur5e" name="ur5e-black" rgba="0.033 0.033 0.033 1"/>
    <material class="ur5e" name="ur5e-jointgray" rgba="0.278 0.278 0.278 1"/>
    <material class="ur5e" name="ur5e-linkgray" rgba="0.82 0.82 0.82 1"/>
    <material class="ur5e" name="ur5e-urblue" rgba="0.49 0.678 0.8 1"/>
    <mesh file="ur5e/base_0.obj"/>
    <mesh file="ur5e/base_1.obj"/>
    <mesh file="ur5e/shoulder_0.obj"/>
    <mesh file="ur5e/shoulder_1.obj"/>
    <mesh file="ur5e/shoulder_2.obj"/>
    <mesh file="ur5e/upperarm_0.obj"/>
    <mesh file="ur5e/upperarm_1.obj"/>
    <mesh file="ur5e/upperarm_2.obj"/>
    <mesh file="ur5e/upperarm_3.obj"/>
    <mesh file="ur5e/forearm_0.obj"/>
    <mesh file="ur5e/forearm_1.obj"/>
    <mesh file="ur5e/forearm_2.obj"/>
    <mesh file="ur5e/forearm_3.obj"/>
    <mesh file="ur5e/wrist1_0.obj"/>
    <mesh file="ur5e/wrist1_1.obj"/>
    <mesh file="ur5e/wrist1_2.obj"/>
    <mesh file="ur5e/wrist2_0.obj"/>
    <mesh file="ur5e/wrist2_1.obj"/>
    <mesh file="ur5e/wrist2_2.obj"/>
    <mesh file="ur5e/wrist3.obj"/>
  </asset>
  <default>
    <default class="ur5e">
      <material specular="0.5" shininess="0.25"/>
      <joint axis="0 1 0" range="-6.28319 6.28319" armature="0.1"/>
      <general gaintype="fixed" biastype="affine" ctrlrange="-6.2831 6.2831" gainprm="2000" biasprm="0 -2000 -400" forcerange="-150 150"/>
      <default class="ur5e-size3">
        <default class="ur5e-size3_limited">
          <joint range="-3.1415 3.1415"/>
          <general ctrlrange="-3.1415 3.1415"/>
        </default>
      </default>
      <default class="ur5e-size1">
        <general gainprm="500" biasprm="0 -500 -100" forcerange="-28 28"/>
      </default>
      <default class="ur5e-visual">
        <geom type="mesh" contype="0" conaffinity="0" group="2"/>
      </default>
      <default class="ur5e-collision">
        <geom type="capsule" group="3"/>
        <default class="ur5e-eef_collision">
          <geom type="cylinder"/>
        </default>
      </default>
      <site size="0.001" rgba="0.5 0.5 0.5 0.3" group="4"/>
    </default>
  </default>
  <worldbody>
    <light pos="0 0 1.5" dir="0 0 -1" directional="true"/>
    <geom name="floor" size="0 0 0.05" type="plane" material="groundplane"/>
    <body name="ur5e" childclass="ur5e" pos="0 0 0" quat="1 0 0 0">
      <inertial mass="4.0" pos="0 0 0" diaginertia="0.00443333156 0.00443333156 0.0072"/>
      <geom mesh="base_0" material="ur5e-black" class="ur5e-visual"/>
      <geom mesh="base_1" material="ur5e-jointgray" class="ur5e-visual"/>
      <body name="ur5e-shoulder_link" pos="0 0 0.163">
        <inertial mass="3.7" pos="0 0 0" diaginertia="0.0102675 0.0102675 0.00666"/>
        <joint name="ur5e-shoulder_pan_joint" class="ur5e-size3" axis="0 0 1"/>
        <geom mesh="shoulder_0" material="ur5e-urblue" class="ur5e-visual"/>
        <geom mesh="shoulder_1" material="ur5e-black" class="ur5e-visual"/>
        <geom mesh="shoulder_2" material="ur5e-jointgray" class="ur5e-visual"/>
        <geom class="ur5e-collision" size="0.06 0.06" pos="0 0 -0.04"/>
        <body name="ur5e-upper_arm_link" pos="0 0.138 0" quat="1 0 1 0">
          <inertial mass="8.393" pos="0 0 0.2125" diaginertia="0.133886 0.133886 0.0151074"/>
          <joint name="ur5e-shoulder_lift_joint" class="ur5e-size3"/>
          <geom mesh="upperarm_0" material="ur5e-linkgray" class="ur5e-visual"/>
          <geom mesh="upperarm_1" material="ur5e-black" class="ur5e-visual"/>
          <geom mesh="upperarm_2" material="ur5e-jointgray" class="ur5e-visual"/>
          <geom mesh="upperarm_3" material="ur5e-urblue" class="ur5e-visual"/>
          <geom class="ur5e-collision" pos="0 -0.04 0" quat="1 1 0 0" size="0.06 0.06"/>
          <geom class="ur5e-collision" size="0.05 0.2" pos="0 0 0.2"/>
          <body name="ur5e-forearm_link" pos="0 -0.131 0.425">
            <inertial mass="2.275" pos="0 0 0.196" diaginertia="0.0311796 0.0311796 0.004095"/>
            <joint name="ur5e-elbow_joint" class="ur5e-size3_limited"/>
            <geom mesh="forearm_0" material="ur5e-urblue" class="ur5e-visual"/>
            <geom mesh="forearm_1" material="ur5e-linkgray" class="ur5e-visual"/>
            <geom mesh="forearm_2" material="ur5e-black" class="ur5e-visual"/>
            <geom mesh="forearm_3" material="ur5e-jointgray" class="ur5e-visual"/>
            <geom class="ur5e-collision" pos="0 0.08 0" quat="1 1 0 0" size="0.055 0.06"/>
            <geom class="ur5e-collision" size="0.038 0.19" pos="0 0 0.2"/>
            <body name="ur5e-wrist_1_link" pos="0 0 0.392" quat="1 0 1 0">
              <inertial mass="1.219" pos="0 0.127 0" diaginertia="0.0025599 0.0025599 0.0021942"/>
              <joint name="ur5e-wrist_1_joint" class="ur5e-size1"/>
              <geom mesh="wrist1_0" material="ur5e-black" class="ur5e-visual"/>
              <geom mesh="wrist1_1" material="ur5e-urblue" class="ur5e-visual"/>
              <geom mesh="wrist1_2" material="ur5e-jointgray" class="ur5e-visual"/>
              <geom class="ur5e-collision" pos="0 0.05 0" quat="1 1 0 0" size="0.04 0.07"/>
              <body name="ur5e-wrist_2_link" pos="0 0.127 0">
                <inertial mass="1.219" pos="0 0 0.1" diaginertia="0.0025599 0.0025599 0.0021942"/>
                <joint name="ur5e-wrist_2_joint" axis="0 0 1" class="ur5e-size1"/>
                <geom mesh="wrist2_0" material="ur5e-black" class="ur5e-visual"/>
                <geom mesh="wrist2_1" material="ur5e-urblue" class="ur5e-visual"/>
                <geom mesh="wrist2_2" material="ur5e-jointgray" class="ur5e-visual"/>
                <geom class="ur5e-collision" size="0.04 0.06" pos="0 0 0.04"/>
                <geom class="ur5e-collision" pos="0 0.02 0.1" quat="1 1 0 0" size="0.04 0.04"/>
                <body name="ur5e-wrist_3_link" pos="0 0 0.1">
                  <inertial mass="0.1889" pos="0 0.0771683 0" quat="1 0 0 1" diaginertia="0.000132134 9.90863e-05 9.90863e-05"/>
                  <joint name="ur5e-wrist_3_joint" class="ur5e-size1"/>
                  <geom material="ur5e-linkgray" mesh="wrist3" class="ur5e-visual" pos="0 0 0.0001"/>
                  <geom class="ur5e-eef_collision" pos="0 0.08 0" quat="1 1 0 0" size="0.04 0.02"/>
                  <site name="ur5e-attachment_site" pos="0 0.1 0" quat="-1 1 0 0"/>
                  <body name="base_mount" childclass="2f85" pos="0 0 0.007">
                    <geom class="2f85-visual" mesh="base_mount" material="black"/>
                    <geom class="2f85-collision" mesh="base_mount"/>
                    <body name="base_mount-base" pos="0 0 0.0038" quat="1 0 0 -1">
                      <inertial mass="0.777441" pos="0 -2.70394e-05 0.0354675" quat="1 -0.00152849 0 0" diaginertia="0.000260285 0.000225381 0.000152708"/>
                      <geom class="2f85-visual" mesh="base" material="black"/>
                      <geom class="2f85-collision" mesh="base"/>
                      <site name="base_mount-pinch" pos="0 0 0.145" type="sphere" group="5" rgba="0.9 0.9 0.9 1" size="0.005"/>
                      <!-- Right-hand side 4-bar linkage -->
                      <body name="base_mount-right_driver" pos="0 0.0306011 0.054904">
                        <inertial mass="0.00899563" pos="2.96931e-12 0.0177547 0.00107314" quat="0.681301 0.732003 0 0" diaginertia="1.72352e-06 1.60906e-06 3.22006e-07"/>
                        <joint name="base_mount-right_driver_joint" class="2f85-driver"/>
                        <geom class="2f85-visual" mesh="driver" material="gray"/>
                        <geom class="2f85-collision" mesh="driver"/>
                        <body name="base_mount-right_coupler" pos="0 0.0315 -0.0041">
                          <inertial mass="0.0140974" pos="0 0.00301209 0.0232175" quat="0.705636 -0.0455904 0.0455904 0.705636" diaginertia="4.16206e-06 3.52216e-06 8.88131e-07"/>
                          <joint name="base_mount-right_coupler_joint" class="2f85-coupler"/>
                          <geom class="2f85-visual" mesh="coupler" material="black"/>
                          <geom class="2f85-collision" mesh="coupler"/>
                        </body>
                      </body>
                      <body name="base_mount-right_spring_link" pos="0 0.0132 0.0609">
                        <inertial mass="0.0221642" pos="-8.65005e-09 0.0181624 0.0212658" quat="0.663403 -0.244737 0.244737 0.663403" diaginertia="8.96853e-06 6.71733e-06 2.63931e-06"/>
                        <joint name="base_mount-right_spring_link_joint" class="2f85-spring_link"/>
                        <geom class="2f85-visual" mesh="spring_link" material="black"/>
                        <geom class="2f85-collision" mesh="spring_link"/>
                        <body name="base_mount-right_follower" pos="0 0.055 0.0375">
                          <inertial mass="0.0125222" pos="0 -0.011046 0.0124786" quat="1 0.1664 0 0" diaginertia="2.67415e-06 2.4559e-06 6.02031e-07"/>
                          <joint name="base_mount-right_follower_joint" class="2f85-follower"/>
                          <geom class="2f85-visual" mesh="follower" material="black"/>
                          <geom class="2f85-collision" mesh="follower"/>
                          <body name="base_mount-right_pad" pos="0 -0.0189 0.01352">
                            <geom class="2f85-pad_box1" name="base_mount-right_pad1"/>
                            <geom class="2f85-pad_box2" name="base_mount-right_pad2"/>
                            <inertial mass="0.0035" pos="0 -0.0025 0.0185" quat="0.707107 0 0 0.707107" diaginertia="4.73958e-07 3.64583e-07 1.23958e-07"/>
                            <geom class="2f85-visual" mesh="pad"/>
                            <body name="base_mount-right_silicone_pad">
                              <geom class="2f85-visual" mesh="silicone_pad" material="black"/>
                            </body>
                          </body>
                        </body>
                      </body>
                      <!-- Left-hand side 4-bar linkage -->
                      <body name="base_mount-left_driver" pos="0 -0.0306011 0.054904" quat="0 0 0 1">
                        <inertial mass="0.00899563" pos="0 0.0177547 0.00107314" quat="0.681301 0.732003 0 0" diaginertia="1.72352e-06 1.60906e-06 3.22006e-07"/>
                        <joint name="base_mount-left_driver_joint" class="2f85-driver"/>
                        <geom class="2f85-visual" mesh="driver" material="gray"/>
                        <geom class="2f85-collision" mesh="driver"/>
                        <body name="base_mount-left_coupler" pos="0 0.0315 -0.0041">
                          <inertial mass="0.0140974" pos="0 0.00301209 0.0232175" quat="0.705636 -0.0455904 0.0455904 0.705636" diaginertia="4.16206e-06 3.52216e-06 8.88131e-07"/>
                          <joint name="base_mount-left_coupler_joint" class="2f85-coupler"/>
                          <geom class="2f85-visual" mesh="coupler" material="black"/>
                          <geom class="2f85-collision" mesh="coupler"/>
                        </body>
                      </body>
                      <body name="base_mount-left_spring_link" pos="0 -0.0132 0.0609" quat="0 0 0 1">
                        <inertial mass="0.0221642" pos="-8.65005e-09 0.0181624 0.0212658" quat="0.663403 -0.244737 0.244737 0.663403" diaginertia="8.96853e-06 6.71733e-06 2.63931e-06"/>
                        <joint name="base_mount-left_spring_link_joint" class="2f85-spring_link"/>
                        <geom class="2f85-visual" mesh="spring_link" material="black"/>
                        <geom class="2f85-collision" mesh="spring_link"/>
                        <body name="base_mount-left_follower" pos="0 0.055 0.0375">
                          <inertial mass="0.0125222" pos="0 -0.011046 0.0124786" quat="1 0.1664 0 0" diaginertia="2.67415e-06 2.4559e-06 6.02031e-07"/>
                          <joint name="base_mount-left_follower_joint" class="2f85-follower"/>
                          <geom class="2f85-visual" mesh="follower" material="black"/>
                          <geom class="2f85-collision" mesh="follower"/>
                          <body name="base_mount-left_pad" pos="0 -0.0189 0.01352">
                            <geom class="2f85-pad_box1" name="base_mount-left_pad1"/>
                            <geom class="2f85-pad_box2" name="base_mount-left_pad2"/>
                            <inertial mass="0.0035" pos="0 -0.0025 0.0185" quat="1 0 0 1" diaginertia="4.73958e-07 3.64583e-07 1.23958e-07"/>
                            <geom class="2f85-visual" mesh="pad"/>
                            <body name="base_mount-left_silicone_pad">
                              <geom class="2f85-visual" mesh="silicone_pad" material="black"/>
                            </body>
                          </body>
                        </body>
                      </body>
                    </body>
                  </body>
                </body>
              </body>
            </body>
          </body>
        </body>
      </body>
    </body>
  </worldbody>
  <actuator>
    <general class="ur5e-size3" name="ur5e-shoulder_pan" joint="ur5e-shoulder_pan_joint"/>
    <general class="ur5e-size3" name="ur5e-shoulder_lift" joint="ur5e-shoulder_lift_joint"/>
    <general class="ur5e-size3_limited" name="ur5e-elbow" joint="ur5e-elbow_joint"/>
    <general class="ur5e-size1" name="ur5e-wrist_1" joint="ur5e-wrist_1_joint"/>
    <general class="ur5e-size1" name="ur5e-wrist_2" joint="ur5e-wrist_2_joint"/>
    <general class="ur5e-size1" name="ur5e-wrist_3" joint="ur5e-wrist_3_joint"/>
  </actuator>
</mujoco>