<?xml version="1.0" ?>
<mujoco model="default stage">
  <compiler angle="radian" autolimits="true"/>
  <statistic center="0.2 0 0.4" extent=".65"/>
  <visual>
    <headlight diffuse="0.6 0.6 0.6" ambient="0.3 0.3 0.3" specular="0 0 0"/>
    <rgba haze="0.15 0.25 0.35 1"/>
    <global azimuth="150" elevation="-20"/>
  </visual>
  <asset>
    <texture type="skybox" builtin="gradient" rgb1="0.3 0.5 0.7" rgb2="0 0 0" width="512" height="3072"/>
    <texture type="2d" name="groundplane" builtin="checker" mark="edge" rgb1="0.2 0.3 0.4" rgb2="0.1 0.2 0.3" markrgb="0.8 0.8 0.8" width="300" height="300"/>
    <material name="groundplane" texture="groundplane" texuniform="true" texrepeat="5 5" reflectance="0.2"/>
    <material class="ur5e" name="ur5e-black" rgba="0.033 0.033 0.033 1"/>
    <material class="ur5e" name="ur5e-jointgray" rgba="0.278 0.278 0.278 1"/>
    <material class="ur5e" name="ur5e-linkgray" rgba="0.82 0.82 0.82 1"/>
    <material class="ur5e" name="ur5e-urblue" rgba="0.49 0.678 0.8 1"/>
    <mesh file="ur5e/base_0.obj"/>
    <mesh file="ur5e/base_1.obj"/>
    <mesh file="ur5e/shoulder_0.obj"/>
    <mesh file="ur5e/shoulder_1.obj"/>
    <mesh file="ur5e/shoulder_2.obj"/>
    <mesh file="ur5e/upperarm_0.obj"/>
    <mesh file="ur5e/upperarm_1.obj"/>
    <mesh file="ur5e/upperarm_2.obj"/>
    <mesh file="ur5e/upperarm_3.obj"/>
    <mesh file="ur5e/forearm_0.obj"/>
    <mesh file="ur5e/forearm_1.obj"/>
    <mesh file="ur5e/forearm_2.obj"/>
    <mesh file="ur5e/forearm_3.obj"/>
    <mesh file="ur5e/wrist1_0.obj"/>
    <mesh file="ur5e/wrist1_1.obj"/>
    <mesh file="ur5e/wrist1_2.obj"/>
    <mesh file="ur5e/wrist2_0.obj"/>
    <mesh file="ur5e/wrist2_1.obj"/>
    <mesh file="ur5e/wrist2_2.obj"/>
    <mesh file="ur5e/wrist3.obj"/>
  </asset>
  <default>
    <default class="ur5e">
      <material specular="0.5" shininess="0.25"/>
      <joint axis="0 1 0" range="-6.28319 6.28319" armature="0.1"/>
      <general gaintype="fixed" biastype="affine" ctrlrange="-6.2831 6.2831" gainprm="2000" biasprm="0 -2000 -400" forcerange="-150 150"/>
      <default class="ur5e-size3">
        <default class="ur5e-size3_limited">
          <joint range="-3.1415 3.1415"/>
          <general ctrlrange="-3.1415 3.1415"/>
        </default>
      </default>
      <default class="ur5e-size1">
        <general gainprm="500" biasprm="0 -500 -100" forcerange="-28 28"/>
      </default>
      <default class="ur5e-visual">
        <geom type="mesh" contype="0" conaffinity="0" group="2"/>
      </default>
      <default class="ur5e-collision">
        <geom type="capsule" group="3"/>
        <default class="ur5e-eef_collision">
          <geom type="cylinder"/>
        </default>
      </default>
      <site size="0.001" rgba="0.5 0.5 0.5 0.3" group="4"/>
    </default>
  </default>
  <worldbody>
    <light pos="0 0 1.5" dir="0 0 -1" directional="true"/>
    <geom name="floor" size="0 0 0.05" type="plane" material="groundplane"/>
    <body name="ur5e" childclass="ur5e" pos="0 0 0" quat="1 0 0 0">
      <inertial mass="4.0" pos="0 0 0" diaginertia="0.00443333156 0.00443333156 0.0072"/>
      <geom mesh="base_0" material="ur5e-black" class="ur5e-visual"/>
      <geom mesh="base_1" material="ur5e-jointgray" class="ur5e-visual"/>
      <body name="ur5e-shoulder_link" pos="0 0 0.163">
        <inertial mass="3.7" pos="0 0 0" diaginertia="0.0102675 0.0102675 0.00666"/>
        <joint name="ur5e-shoulder_pan_joint" class="ur5e-size3" axis="0 0 1"/>
        <geom mesh="shoulder_0" material="ur5e-urblue" class="ur5e-visual"/>
        <geom mesh="shoulder_1" material="ur5e-black" class="ur5e-visual"/>
        <geom mesh="shoulder_2" material="ur5e-jointgray" class="ur5e-visual"/>
        <geom class="ur5e-collision" size="0.06 0.06" pos="0 0 -0.04"/>
        <body name="ur5e-upper_arm_link" pos="0 0.138 0" quat="1 0 1 0">
          <inertial mass="8.393" pos="0 0 0.2125" diaginertia="0.133886 0.133886 0.0151074"/>
          <joint name="ur5e-shoulder_lift_joint" class="ur5e-size3"/>
          <geom mesh="upperarm_0" material="ur5e-linkgray" class="ur5e-visual"/>
          <geom mesh="upperarm_1" material="ur5e-black" class="ur5e-visual"/>
          <geom mesh="upperarm_2" material="ur5e-jointgray" class="ur5e-visual"/>
          <geom mesh="upperarm_3" material="ur5e-urblue" class="ur5e-visual"/>
          <geom class="ur5e-collision" pos="0 -0.04 0" quat="1 1 0 0" size="0.06 0.06"/>
          <geom class="ur5e-collision" size="0.05 0.2" pos="0 0 0.2"/>
          <body name="ur5e-forearm_link" pos="0 -0.131 0.425">
            <inertial mass="2.275" pos="0 0 0.196" diaginertia="0.0311796 0.0311796 0.004095"/>
            <joint name="ur5e-elbow_joint" class="ur5e-size3_limited"/>
            <geom mesh="forearm_0" material="ur5e-urblue" class="ur5e-visual"/>
            <geom mesh="forearm_1" material="ur5e-linkgray" class="ur5e-visual"/>
            <geom mesh="forearm_2" material="ur5e-black" class="ur5e-visual"/>
            <geom mesh="forearm_3" material="ur5e-jointgray" class="ur5e-visual"/>
            <geom class="ur5e-collision" pos="0 0.08 0" quat="1 1 0 0" size="0.055 0.06"/>
            <geom class="ur5e-collision" size="0.038 0.19" pos="0 0 0.2"/>
            <body name="ur5e-wrist_1_link" pos="0 0 0.392" quat="1 0 1 0">
              <inertial mass="1.219" pos="0 0.127 0" diaginertia="0.0025599 0.0025599 0.0021942"/>
              <joint name="ur5e-wrist_1_joint" class="ur5e-size1"/>
              <geom mesh="wrist1_0" material="ur5e-black" class="ur5e-visual"/>
              <geom mesh="wrist1_1" material="ur5e-urblue" class="ur5e-visual"/>
              <geom mesh="wrist1_2" material="ur5e-jointgray" class="ur5e-visual"/>
              <geom class="ur5e-collision" pos="0 0.05 0" quat="1 1 0 0" size="0.04 0.07"/>
              <body name="ur5e-wrist_2_link" pos="0 0.127 0">
                <inertial mass="1.219" pos="0 0 0.1" diaginertia="0.0025599 0.0025599 0.0021942"/>
                <joint name="ur5e-wrist_2_joint" axis="0 0 1" class="ur5e-size1"/>
                <geom mesh="wrist2_0" material="ur5e-black" class="ur5e-visual"/>
                <geom mesh="wrist2_1" material="ur5e-urblue" class="ur5e-visual"/>
                <geom mesh="wrist2_2" material="ur5e-jointgray" class="ur5e-visual"/>
                <geom class="ur5e-collision" size="0.04 0.06" pos="0 0 0.04"/>
                <geom class="ur5e-collision" pos="0 0.02 0.1" quat="1 1 0 0" size="0.04 0.04"/>
                <body name="ur5e-wrist_3_link" pos="0 0 0.1">
                  <inertial mass="0.1889" pos="0 0.0771683 0" quat="1 0 0 1" diaginertia="0.000132134 9.90863e-05 9.90863e-05"/>
                  <joint name="ur5e-wrist_3_joint" class="ur5e-size1"/>
                  <geom material="ur5e-linkgray" mesh="wrist3" class="ur5e-visual" pos="0 0 0.0001"/>
                  <geom class="ur5e-eef_collision" pos="0 0.08 0" quat="1 1 0 0" size="0.04 0.02"/>
                  <site name="ur5e-attachment_site" pos="0 0.1 0" quat="-1 1 0 0"/>
                </body>
              </body>
            </body>
          </body>
        </body>
      </body>
    </body>
  </worldbody>
  <actuator>
    <general class="ur5e-size3" name="ur5e-shoulder_pan" joint="ur5e-shoulder_pan_joint"/>
    <general class="ur5e-size3" name="ur5e-shoulder_lift" joint="ur5e-shoulder_lift_joint"/>
    <general class="ur5e-size3_limited" name="ur5e-elbow" joint="ur5e-elbow_joint"/>
    <general class="ur5e-size1" name="ur5e-wrist_1" joint="ur5e-wrist_1_joint"/>
    <general class="ur5e-size1" name="ur5e-wrist_2" joint="ur5e-wrist_2_joint"/>
    <general class="ur5e-size1" name="ur5e-wrist_3" joint="ur5e-wrist_3_joint"/>
  </actuator>
</mujoco>