<mujoco model="ability_hand">
  <compiler angle="radian" meshdir="assets/"/>

  <asset>
    <mesh name="wristmesh" file="wristmesh.obj"/>
    <mesh name="wristmesh_C" file="wristmesh_C.obj"/>
    <mesh name="FB_palm_ref_MIR" file="FB_palm_ref_MIR.obj"/>
    <mesh name="idx-F1" file="idx-F1.obj"/>
    <mesh name="idx-F2" file="idx-F2.obj"/>
    <mesh name="idx-F2_C" file="idx-F2_C.obj"/>
    <mesh name="thumb-F1-MIR" file="thumb-F1-MIR.obj"/>
    <mesh name="thumb-F1-MIR_C" file="thumb-F1-MIR_C.obj"/>
    <mesh name="thumb-F2" file="thumb-F2.obj"/>
    <mesh name="thumb-F2_C" file="thumb-F2_C.obj"/>
  </asset>

  <worldbody>
    <geom name="wrist_mesh" type="mesh" contype="0" conaffinity="0" group="1" density="0" mesh="wristmesh"/>
    <geom type="mesh" mesh="wristmesh_C"/>
    <geom name="palm_mesh" pos="-0.0240477 0.00378125 0.0323296" quat="0.0442297 0.00061027 -0.999021 -2.70192e-05" type="mesh" contype="0" conaffinity="0" group="1" density="0" mesh="FB_palm_ref_MIR"/>
    <geom pos="-0.0240477 0.00378125 0.0323296" quat="0.0442297 0.00061027 -0.999021 -2.70192e-05" type="mesh" mesh="FB_palm_ref_MIR"/>
    <body name="index_L1" pos="-0.0279216 -0.00927034 0.0958706" quat="0.685906 0.0469401 -0.714459 -0.129917">
      <inertial pos="0.0224191 -0.000157982 -1.31987e-05" quat="-0.00406251 0.706621 0.00934715 0.707518" mass="0.00635888" diaginertia="0.000381765 0.000369601 2.96432e-05"/>
      <joint name="index_q1" pos="0 0 0" axis="0 0 1" range="0 2.0944" actuatorfrcrange="-6 6" damping="0.001" frictionloss="0.001"/>
      <geom name="index_mesh_1" pos="0.0384727 0.0032577 0" quat="0.999108 0 0 0.0422244" type="mesh" contype="0" conaffinity="0" group="1" density="0" mesh="idx-F1"/>
      <geom size="0.0085" pos="0.036 -0.00175 0"/>
      <geom size="0.014 0.006 0.008" pos="0.019 -0.0045 0" quat="0.999108 0 0 0.0422374" type="box"/>
      <geom size="0.006 0.006 0.001" pos="-0.001 0 0.007" quat="0.999108 0 0 0.0422374" type="box"/>
      <geom size="0.006 0.006 0.001" pos="-0.001 0 -0.007" quat="0.999108 0 0 0.0422374" type="box"/>
      <body name="index_L2" pos="0.0384727 0.0032577 0" quat="0.999108 0 0 0.0422244">
        <inertial pos="0.0133682 -0.00875392 -2.886e-05" quat="-0.161363 0.673074 0.216775 0.688434" mass="0.00645" diaginertia="0.000264645 0.000263553 1.71391e-05"/>
        <joint name="index_q2" pos="0 0 0" axis="0 0 1" range="0 2.6586" actuatorfrcrange="-6 6" damping="0.001" frictionloss="0.001"/>
        <geom name="index_mesh_2" pos="0.0091241 0 0" quat="1 0 0 0" type="mesh" contype="0" conaffinity="0" group="1" density="0" mesh="idx-F2"/>
        <geom type="mesh" mesh="idx-F2_C"/>
        <geom size="0.007" pos="0.03 -0.016 0"/>
      </body>
    </body>
    <body name="middle_L1" pos="-0.00841718 -0.0115172 0.0990634" quat="0.704562 0.0715738 -0.698395 -0.103508">
      <inertial pos="0.0224191 -0.000157982 -1.31987e-05" quat="-0.00406251 0.706621 0.00934715 0.707518" mass="0.00635888" diaginertia="0.000381765 0.000369601 2.96432e-05"/>
      <joint name="middle_q1" pos="0 0 0" axis="0 0 1" range="0 2.0944" actuatorfrcrange="-6 6" damping="0.001" frictionloss="0.001"/>
      <geom name="middle_mesh_1" pos="0.0384727 0.0032577 0" quat="0.999108 0 0 0.0422244" type="mesh" contype="0" conaffinity="0" group="1" density="0" mesh="idx-F1"/>
      <geom size="0.0085" pos="0.036 -0.00175 0"/>
      <geom size="0.014 0.006 0.008" pos="0.019 -0.0045 0" quat="0.999108 0 0 0.0422374" type="box"/>
      <geom size="0.01 0.005 0.008" pos="0.018 0.006 0" quat="0.999108 0 0 0.0422374" type="box"/>
      <geom size="0.006 0.006 0.001" pos="-0.001 0 0.007" quat="0.999108 0 0 0.0422374" type="box"/>
      <geom size="0.006 0.006 0.001" pos="-0.001 0 -0.007" quat="0.999108 0 0 0.0422374" type="box"/>
      <body name="middle_L2" pos="0.0384727 0.0032577 0" quat="0.999108 0 0 0.0422244">
        <inertial pos="0.0133682 -0.00875392 -2.886e-05" quat="-0.161363 0.673074 0.216775 0.688434" mass="0.00645" diaginertia="0.000264645 0.000263553 1.71391e-05"/>
        <joint name="middle_q2" pos="0 0 0" axis="0 0 1" range="0 2.6586" actuatorfrcrange="-6 6" damping="0.001" frictionloss="0.001"/>
        <geom name="middle_mesh_2" pos="0.0091241 0 0" quat="1 0 0 0" type="mesh" contype="0" conaffinity="0" group="1" density="0" mesh="idx-F2"/>
        <geom type="mesh" mesh="idx-F2_C"/>
        <geom size="0.007" pos="0.03 -0.016 0"/>
      </body>
    </body>
    <body name="ring_L1" pos="0.0117529 -0.0103946 0.0967038" quat="0.721351 0.0986547 -0.681173 -0.0769649">
      <inertial pos="0.0224191 -0.000157982 -1.31987e-05" quat="-0.00406251 0.706621 0.00934715 0.707518" mass="0.00635888" diaginertia="0.000381765 0.000369601 2.96432e-05"/>
      <joint name="ring_q1" pos="0 0 0" axis="0 0 1" range="0 2.0944" actuatorfrcrange="-6 6" damping="0.001" frictionloss="0.001"/>
      <geom name="ring_mesh_1" pos="0.0384727 0.0032577 0" quat="0.999108 0 0 0.0422244" type="mesh" contype="0" conaffinity="0" group="1" density="0" mesh="idx-F1"/>
      <geom size="0.0085" pos="0.036 -0.00175 0"/>
      <geom size="0.014 0.006 0.008" pos="0.019 -0.0045 0" quat="0.999108 0 0 0.0422374" type="box"/>
      <geom size="0.01 0.005 0.008" pos="0.018 0.006 0" quat="0.999108 0 0 0.0422374" type="box"/>
      <geom size="0.006 0.006 0.001" pos="-0.001 0 0.007" quat="0.999108 0 0 0.0422374" type="box"/>
      <geom size="0.006 0.006 0.001" pos="-0.001 0 -0.007" quat="0.999108 0 0 0.0422374" type="box"/>
      <body name="ring_L2" pos="0.0384727 0.0032577 0" quat="0.999108 0 0 0.0422244">
        <inertial pos="0.0133682 -0.00875392 -2.886e-05" quat="-0.161363 0.673074 0.216775 0.688434" mass="0.00645" diaginertia="0.000264645 0.000263553 1.71391e-05"/>
        <joint name="ring_q2" pos="0 0 0" axis="0 0 1" range="0 2.6586" actuatorfrcrange="-6 6" damping="0.001" frictionloss="0.001"/>
        <geom name="ring_mesh_2" pos="0.0091241 0 0" quat="1 0 0 0" type="mesh" contype="0" conaffinity="0" group="1" density="0" mesh="idx-F2"/>
        <geom type="mesh" mesh="idx-F2_C"/>
        <geom size="0.007" pos="0.03 -0.016 0"/>
      </body>
    </body>
    <body name="pinky_L1" pos="0.0308633 -0.00716283 0.0907346" quat="0.719226 0.122363 -0.681748 -0.0544096">
      <inertial pos="0.0224191 -0.000157982 -1.31987e-05" quat="-0.00406251 0.706621 0.00934715 0.707518" mass="0.00635888" diaginertia="0.000381765 0.000369601 2.96432e-05"/>
      <joint name="pinky_q1" pos="0 0 0" axis="0 0 1" range="0 2.0944" actuatorfrcrange="-6 6" damping="0.001" frictionloss="0.001"/>
      <geom name="pinky_mesh_1" pos="0.0384727 0.0032577 0" quat="0.999108 0 0 0.0422244" type="mesh" contype="0" conaffinity="0" group="1" density="0" mesh="idx-F1"/>
      <geom size="0.0085" pos="0.036 -0.00175 0"/>
      <geom size="0.014 0.006 0.008" pos="0.019 -0.0045 0" quat="0.999108 0 0 0.0422374" type="box"/>
      <geom size="0.01 0.005 0.008" pos="0.018 0.006 0" quat="0.999108 0 0 0.0422374" type="box"/>
      <geom size="0.006 0.006 0.001" pos="-0.001 0 0.007" quat="0.999108 0 0 0.0422374" type="box"/>
      <geom size="0.006 0.006 0.001" pos="-0.001 0 -0.007" quat="0.999108 0 0 0.0422374" type="box"/>
      <body name="pinky_L2" pos="0.0384727 0.0032577 0" quat="0.999108 0 0 0.0422244">
        <inertial pos="0.0133682 -0.00875392 -2.886e-05" quat="-0.161363 0.673074 0.216775 0.688434" mass="0.00645" diaginertia="0.000264645 0.000263553 1.71391e-05"/>
        <joint name="pinky_q2" pos="0 0 0" axis="0 0 1" range="0 2.6586" actuatorfrcrange="-6 6" damping="0.001" frictionloss="0.001"/>
        <geom name="pinky_mesh_2" pos="0.0091241 0 0" quat="1 0 0 0" type="mesh" contype="0" conaffinity="0" group="1" density="0" mesh="idx-F2"/>
        <geom type="mesh" mesh="idx-F2_C"/>
        <geom size="0.007" pos="0.03 -0.016 0"/>
      </body>
    </body>
    <body name="thumb_L1" pos="-0.0240477 0.00378125 0.0323296" quat="-0.0947972 0.0440301 -0.00419696 0.994514">
      <inertial pos="0.014606 -0.00189085 -0.00311554" quat="0.306728 0.531258 0.293089 0.733336" mass="0.00268342" diaginertia="8.14795e-05 7.42718e-05 1.14409e-05"/>
      <joint name="thumb_q1" pos="0 0 0" axis="0 0 1" range="-2.0944 0" actuatorfrcrange="-1.2 1.2" damping="0.001" frictionloss="0.001"/>
      <geom name="thumb_mesh_1" pos="0.0278284 0 0.0147507" quat="0.608761 0.793353 0 0" type="mesh" contype="0" conaffinity="0" group="1" density="0" mesh="thumb-F1-MIR"/>
      <geom pos="0.0278284 0 0.0147507" quat="0.608761 0.793353 0 0" type="mesh" mesh="thumb-F1-MIR_C"/>
      <body name="thumb_L2" pos="0.0278284 0 0.0147507" quat="0.608761 0.793353 0 0">
        <inertial pos="0.0300205 0.00559476 -0.00415044" quat="0.00721249 0.656735 -0.223684 0.720148" mass="0.0055" diaginertia="0.00180207 0.00170892 0.000287855"/>
        <joint name="thumb_q2" pos="0 0 0" axis="0 0 1" range="0 2.0944" actuatorfrcrange="-6 6" damping="0.001" frictionloss="0.001"/>
        <geom name="thumb_mesh_2" pos="0.0651867 0.0233402 0.00393483" quat="3.21978e-07 -0.985259 -0.171069 5.59046e-08" type="mesh" contype="0" conaffinity="0" group="1" density="0" mesh="thumb-F2"/>
        <geom pos="0.0651867 0.0233402 0.00393483" quat="3.21978e-07 -0.985259 -0.171069 5.59046e-08" type="mesh" mesh="thumb-F2_C"/>
      </body>
    </body>
  </worldbody>

  <actuator>
    <position name="act_index_q1" joint="index_q1" kp="50" kv="0.5" ctrlrange="0 2.0944" forcerange="-6 6"/>
    <position name="act_index_q2" joint="index_q2" kp="50" kv="0.5" ctrlrange="0 2.6586" forcerange="-6 6"/>
    
    <position name="act_middle_q1" joint="middle_q1" kp="50" kv="0.5" ctrlrange="0 2.0944" forcerange="-6 6"/>
    <position name="act_middle_q2" joint="middle_q2" kp="50" kv="0.5" ctrlrange="0 2.6586" forcerange="-6 6"/>
    
    <position name="act_ring_q1" joint="ring_q1" kp="50" kv="0.5" ctrlrange="0 2.0944" forcerange="-6 6"/>
    <position name="act_ring_q2" joint="ring_q2" kp="50" kv="0.5" ctrlrange="0 2.6586" forcerange="-6 6"/>
    
    <position name="act_pinky_q1" joint="pinky_q1" kp="50" kv="0.5" ctrlrange="0 2.0944" forcerange="-6 6"/>
    <position name="act_pinky_q2" joint="pinky_q2" kp="50" kv="0.5" ctrlrange="0 2.6586" forcerange="-6 6"/>
    
    <position name="act_thumb_q1" joint="thumb_q1" kp="50" kv="0.5" ctrlrange="-2.0944 0" forcerange="-6 6"/>
    <position name="act_thumb_q2" joint="thumb_q2" kp="50" kv="0.5" ctrlrange="0 2.0944" forcerange="-6 6"/>
</actuator>
</mujoco>
