<mujoco model="xarm7 right ability hand">
  <compiler angle="radian" autolimits="true" meshdir="assets"/>

  <option integrator="implicitfast"/>

  <asset>
    <material name="white" rgba="1 1 1 1"/>
    <material name="gray" rgba="0.753 0.753 0.753 1"/>

    <mesh file="link_base.stl"/>
    <mesh file="link1.stl"/>
    <mesh file="link2.stl"/>
    <mesh file="link3.stl"/>
    <mesh file="link4.stl"/>
    <mesh file="link5.stl"/>
    <mesh file="link6.stl"/>
    <mesh file="link7.stl"/>
    <mesh file="end_tool.stl"/>
    
    <mesh name="wristmesh" file="wristmesh.obj"/>
    <mesh name="wristmesh_C" file="wristmesh_C.obj"/>
    <mesh name="FB_palm_ref_MIR" file="FB_palm_ref_MIR.obj"/>
    <mesh name="idx-F1" file="idx-F1.obj"/>
    <mesh name="idx-F2" file="idx-F2.obj"/>
    <mesh name="idx-F2_C" file="idx-F2_C.obj"/>
    <mesh name="thumb-F1-MIR" file="thumb-F1-MIR.obj"/>
    <mesh name="thumb-F1-MIR_C" file="thumb-F1-MIR_C.obj"/>
    <mesh name="thumb-F2" file="thumb-F2.obj"/>
    <mesh name="thumb-F2_C" file="thumb-F2_C.obj"/>
  </asset>

  <default>
    <default class="xarm7">
      <geom type="mesh" material="white"/>
      <joint axis="0 0 1" range="-6.28319 6.28319" frictionloss="1"/>
      <general biastype="affine" ctrlrange="-6.28319 6.28319"/>
      <default class="size1">
        <joint damping="10"/>
        <general gainprm="1500" biasprm="0 -1500 -150" forcerange="-50 50"/>
      </default>
      <default class="size2">
        <joint damping="5"/>
        <general gainprm="1000" biasprm="0 -1000 -100" forcerange="-30 30"/>
      </default>
      <default class="size3">
        <joint damping="2"/>
        <general gainprm="800" biasprm="0 -800 -80" forcerange="-20 20"/>
      </default>
      <site size="0.001" rgba="1 0 0 1" group="4"/>
    </default>
  </default>

  <worldbody>
    <body name="link_base" pos="-0.3 -0.35 0.765" childclass="xarm7">
      <inertial pos="-0.021131 -0.0016302 0.056488" quat="0.696843 0.20176 0.10388 0.680376" mass="0.88556"
        diaginertia="0.00382023 0.00335282 0.00167725"/>
      <geom mesh="link_base"/>
      <body name="link1" pos="0 0 0.267">
        <inertial pos="-0.0002 0.02905 -0.01233" quat="0.978953 -0.202769 -0.00441617 -0.0227264" mass="2.382"
          diaginertia="0.00569127 0.00533384 0.00293865"/>
        <joint name="joint1" class="size1"/>
        <geom mesh="link1"/>
        <body name="link2" quat="1 -1 0 0">
          <inertial pos="0.00022 -0.12856 0.01735" quat="0.50198 0.86483 -0.00778841 0.00483285" mass="1.869"
            diaginertia="0.00959898 0.00937717 0.00201315"/>
          <joint name="joint2" range="-2.059 2.0944" class="size1"/>
          <geom mesh="link2"/>
          <body name="link3" pos="0 -0.293 0" quat="1 1 0 0">
            <inertial pos="0.0466 -0.02463 -0.00768" quat="0.913819 0.289775 0.281481 -0.0416455" mass="1.6383"
              diaginertia="0.00351721 0.00294089 0.00195868"/>
            <joint name="joint3" class="size2"/>
            <geom mesh="link3"/>
            <body name="link4" pos="0.0525 0 0" quat="1 1 0 0">
              <inertial pos="0.07047 -0.11575 0.012" quat="0.422108 0.852026 -0.126025 0.282832" mass="1.7269"
                diaginertia="0.00657137 0.00647948 0.00186763"/>
              <joint name="joint4" range="-0.19198 3.927" class="size2"/>
              <geom mesh="link4"/>
              <body name="link5" pos="0.0775 -0.3425 0" quat="1 1 0 0">
                <inertial pos="-0.00032 0.01604 -0.026" quat="0.999311 -0.0304457 0.000577067 0.0212082" mass="1.3203"
                  diaginertia="0.00534729 0.00499076 0.0013489"/>
                <joint name="joint5" class="size2"/>
                <geom mesh="link5"/>
                <body name="link6" quat="1 1 0 0">
                  <inertial pos="0.06469 0.03278 0.02141" quat="-0.217672 0.772419 0.16258 0.574069" mass="1.325"
                    diaginertia="0.00245421 0.00221646 0.00107273"/>
                  <joint name="joint6" range="-1.69297 3.14159" class="size3"/>
                  <geom mesh="link6"/>
                  <body name="link7" pos="0.076 0.097 0" quat="1 -1 0 0">
                    <inertial pos="0 -0.00677 -0.01098" quat="0.487612 0.512088 -0.512088 0.487612" mass="0.17"
                      diaginertia="0.000132176 9.3e-05 5.85236e-05"/>
                    <joint name="joint7" class="size3"/>
                    <geom material="gray" mesh="end_tool"/>
                    <site name="attachment_site"/>





                    <geom name="wrist_mesh" type="mesh" contype="0" conaffinity="0" group="1" density="0" mesh="wristmesh"/>
                    <geom type="mesh" mesh="wristmesh_C"/>
                    <geom name="palm_mesh" pos="-0.0240477 0.00378125 0.0323296" quat="0.0442297 0.00061027 -0.999021 -2.70192e-05" type="mesh" contype="0" conaffinity="0" group="1" density="0" mesh="FB_palm_ref_MIR"/>
                    <geom pos="-0.0240477 0.00378125 0.0323296" quat="0.0442297 0.00061027 -0.999021 -2.70192e-05" type="mesh" mesh="FB_palm_ref_MIR"/>
                    <body name="index_L1" pos="-0.0279216 -0.00927034 0.0958706" quat="0.685906 0.0469401 -0.714459 -0.129917">
                      <inertial pos="0.0224191 -0.000157982 -1.31987e-05" quat="-0.00406251 0.706621 0.00934715 0.707518" mass="0.00635888" diaginertia="0.000381765 0.000369601 2.96432e-05"/>
                      <joint name="index_q1" pos="0 0 0" axis="0 0 1" range="0 2.0944" actuatorfrcrange="-6 6" damping="0.001" frictionloss="0.001"/>
                      <geom name="index_mesh_1" pos="0.0384727 0.0032577 0" quat="0.999108 0 0 0.0422244" type="mesh" contype="0" conaffinity="0" group="1" density="0" mesh="idx-F1"/>
                      <geom type="sphere" size="0.0085" pos="0.036 -0.00175 0"/>
                      <geom size="0.014 0.006 0.008" pos="0.019 -0.0045 0" quat="0.999108 0 0 0.0422374" type="box"/>
                      <geom size="0.006 0.006 0.001" pos="-0.001 0 0.007" quat="0.999108 0 0 0.0422374" type="box"/>
                      <geom size="0.006 0.006 0.001" pos="-0.001 0 -0.007" quat="0.999108 0 0 0.0422374" type="box"/>
                      <body name="index_L2" pos="0.0384727 0.0032577 0" quat="0.999108 0 0 0.0422244">
                        <inertial pos="0.0133682 -0.00875392 -2.886e-05" quat="-0.161363 0.673074 0.216775 0.688434" mass="0.00645" diaginertia="0.000264645 0.000263553 1.71391e-05"/>
                        <joint name="index_q2" pos="0 0 0" axis="0 0 1" range="0 2.6586" actuatorfrcrange="-6 6" damping="0.001" frictionloss="0.001"/>
                        <geom name="index_mesh_2" pos="0.0091241 0 0" quat="1 0 0 0" type="mesh" contype="0" conaffinity="0" group="1" density="0" mesh="idx-F2"/>
                        <geom type="mesh" mesh="idx-F2_C"/>
                        <geom type="sphere" size="0.007" pos="0.03 -0.016 0"/>
                      </body>
                    </body>
                    <body name="middle_L1" pos="-0.00841718 -0.0115172 0.0990634" quat="0.704562 0.0715738 -0.698395 -0.103508">
                      <inertial pos="0.0224191 -0.000157982 -1.31987e-05" quat="-0.00406251 0.706621 0.00934715 0.707518" mass="0.00635888" diaginertia="0.000381765 0.000369601 2.96432e-05"/>
                      <joint name="middle_q1" pos="0 0 0" axis="0 0 1" range="0 2.0944" actuatorfrcrange="-6 6" damping="0.001" frictionloss="0.001"/>
                      <geom name="middle_mesh_1" pos="0.0384727 0.0032577 0" quat="0.999108 0 0 0.0422244" type="mesh" contype="0" conaffinity="0" group="1" density="0" mesh="idx-F1"/>
                      <geom type="sphere" size="0.0085" pos="0.036 -0.00175 0"/>
                      <geom size="0.014 0.006 0.008" pos="0.019 -0.0045 0" quat="0.999108 0 0 0.0422374" type="box"/>
                      <geom size="0.01 0.005 0.008" pos="0.018 0.006 0" quat="0.999108 0 0 0.0422374" type="box"/>
                      <geom size="0.006 0.006 0.001" pos="-0.001 0 0.007" quat="0.999108 0 0 0.0422374" type="box"/>
                      <geom size="0.006 0.006 0.001" pos="-0.001 0 -0.007" quat="0.999108 0 0 0.0422374" type="box"/>
                      <body name="middle_L2" pos="0.0384727 0.0032577 0" quat="0.999108 0 0 0.0422244">
                        <inertial pos="0.0133682 -0.00875392 -2.886e-05" quat="-0.161363 0.673074 0.216775 0.688434" mass="0.00645" diaginertia="0.000264645 0.000263553 1.71391e-05"/>
                        <joint name="middle_q2" pos="0 0 0" axis="0 0 1" range="0 2.6586" actuatorfrcrange="-6 6" damping="0.001" frictionloss="0.001"/>
                        <geom name="middle_mesh_2" pos="0.0091241 0 0" quat="1 0 0 0" type="mesh" contype="0" conaffinity="0" group="1" density="0" mesh="idx-F2"/>
                        <geom type="mesh" mesh="idx-F2_C"/>
                        <geom type="sphere" size="0.007" pos="0.03 -0.016 0"/>
                      </body>
                    </body>
                    <body name="ring_L1" pos="0.0117529 -0.0103946 0.0967038" quat="0.721351 0.0986547 -0.681173 -0.0769649">
                      <inertial pos="0.0224191 -0.000157982 -1.31987e-05" quat="-0.00406251 0.706621 0.00934715 0.707518" mass="0.00635888" diaginertia="0.000381765 0.000369601 2.96432e-05"/>
                      <joint name="ring_q1" pos="0 0 0" axis="0 0 1" range="0 2.0944" actuatorfrcrange="-6 6" damping="0.001" frictionloss="0.001"/>
                      <geom name="ring_mesh_1" pos="0.0384727 0.0032577 0" quat="0.999108 0 0 0.0422244" type="mesh" contype="0" conaffinity="0" group="1" density="0" mesh="idx-F1"/>
                      <geom type="sphere" size="0.0085" pos="0.036 -0.00175 0"/>
                      <geom size="0.014 0.006 0.008" pos="0.019 -0.0045 0" quat="0.999108 0 0 0.0422374" type="box"/>
                      <geom size="0.01 0.005 0.008" pos="0.018 0.006 0" quat="0.999108 0 0 0.0422374" type="box"/>
                      <geom size="0.006 0.006 0.001" pos="-0.001 0 0.007" quat="0.999108 0 0 0.0422374" type="box"/>
                      <geom size="0.006 0.006 0.001" pos="-0.001 0 -0.007" quat="0.999108 0 0 0.0422374" type="box"/>
                      <body name="ring_L2" pos="0.0384727 0.0032577 0" quat="0.999108 0 0 0.0422244">
                        <inertial pos="0.0133682 -0.00875392 -2.886e-05" quat="-0.161363 0.673074 0.216775 0.688434" mass="0.00645" diaginertia="0.000264645 0.000263553 1.71391e-05"/>
                        <joint name="ring_q2" pos="0 0 0" axis="0 0 1" range="0 2.6586" actuatorfrcrange="-6 6" damping="0.001" frictionloss="0.001"/>
                        <geom name="ring_mesh_2" pos="0.0091241 0 0" quat="1 0 0 0" type="mesh" contype="0" conaffinity="0" group="1" density="0" mesh="idx-F2"/>
                        <geom type="mesh" mesh="idx-F2_C"/>
                        <geom type="sphere" size="0.007" pos="0.03 -0.016 0"/>
                      </body>
                    </body>
                    <body name="pinky_L1" pos="0.0308633 -0.00716283 0.0907346" quat="0.719226 0.122363 -0.681748 -0.0544096">
                      <inertial pos="0.0224191 -0.000157982 -1.31987e-05" quat="-0.00406251 0.706621 0.00934715 0.707518" mass="0.00635888" diaginertia="0.000381765 0.000369601 2.96432e-05"/>
                      <joint name="pinky_q1" pos="0 0 0" axis="0 0 1" range="0 2.0944" actuatorfrcrange="-6 6" damping="0.001" frictionloss="0.001"/>
                      <geom name="pinky_mesh_1" pos="0.0384727 0.0032577 0" quat="0.999108 0 0 0.0422244" type="mesh" contype="0" conaffinity="0" group="1" density="0" mesh="idx-F1"/>
                      <geom type="sphere" size="0.0085" pos="0.036 -0.00175 0"/>
                      <geom size="0.014 0.006 0.008" pos="0.019 -0.0045 0" quat="0.999108 0 0 0.0422374" type="box"/>
                      <geom size="0.01 0.005 0.008" pos="0.018 0.006 0" quat="0.999108 0 0 0.0422374" type="box"/>
                      <geom size="0.006 0.006 0.001" pos="-0.001 0 0.007" quat="0.999108 0 0 0.0422374" type="box"/>
                      <geom size="0.006 0.006 0.001" pos="-0.001 0 -0.007" quat="0.999108 0 0 0.0422374" type="box"/>
                      <body name="pinky_L2" pos="0.0384727 0.0032577 0" quat="0.999108 0 0 0.0422244">
                        <inertial pos="0.0133682 -0.00875392 -2.886e-05" quat="-0.161363 0.673074 0.216775 0.688434" mass="0.00645" diaginertia="0.000264645 0.000263553 1.71391e-05"/>
                        <joint name="pinky_q2" pos="0 0 0" axis="0 0 1" range="0 2.6586" actuatorfrcrange="-6 6" damping="0.001" frictionloss="0.001"/>
                        <geom name="pinky_mesh_2" pos="0.0091241 0 0" quat="1 0 0 0" type="mesh" contype="0" conaffinity="0" group="1" density="0" mesh="idx-F2"/>
                        <geom type="mesh" mesh="idx-F2_C"/>
                        <geom type="sphere" size="0.007" pos="0.03 -0.016 0"/>
                      </body>
                    </body>
                    <body name="thumb_L1" pos="-0.0240477 0.00378125 0.0323296" quat="-0.0947972 0.0440301 -0.00419696 0.994514">
                      <inertial pos="0.014606 -0.00189085 -0.00311554" quat="0.306728 0.531258 0.293089 0.733336" mass="0.00268342" diaginertia="8.14795e-05 7.42718e-05 1.14409e-05"/>
                      <joint name="thumb_q1" pos="0 0 0" axis="0 0 1" range="-2.0944 0" actuatorfrcrange="-1.2 1.2" damping="0.001" frictionloss="0.001"/>
                      <geom name="thumb_mesh_1" pos="0.0278284 0 0.0147507" quat="0.608761 0.793353 0 0" type="mesh" contype="0" conaffinity="0" group="1" density="0" mesh="thumb-F1-MIR"/>
                      <geom pos="0.0278284 0 0.0147507" quat="0.608761 0.793353 0 0" type="mesh" mesh="thumb-F1-MIR_C"/>
                      <body name="thumb_L2" pos="0.0278284 0 0.0147507" quat="0.608761 0.793353 0 0">
                        <inertial pos="0.0300205 0.00559476 -0.00415044" quat="0.00721249 0.656735 -0.223684 0.720148" mass="0.0055" diaginertia="0.00180207 0.00170892 0.000287855"/>
                        <joint name="thumb_q2" pos="0 0 0" axis="0 0 1" range="0 2.0944" actuatorfrcrange="-6 6" damping="0.001" frictionloss="0.001"/>
                        <geom name="thumb_mesh_2" pos="0.0651867 0.0233402 0.00393483" quat="3.21978e-07 -0.985259 -0.171069 5.59046e-08" type="mesh" contype="0" conaffinity="0" group="1" density="0" mesh="thumb-F2"/>
                        <geom pos="0.0651867 0.0233402 0.00393483" quat="3.21978e-07 -0.985259 -0.171069 5.59046e-08" type="mesh" mesh="thumb-F2_C"/>
                      </body>
                    </body>




                  </body>
                </body>
              </body>
            </body>
          </body>
        </body>
      </body>
    </body>
  </worldbody>

  <actuator>
    <general name="act1" joint="joint1" class="size1"/>
    <general name="act2" joint="joint2" class="size1" ctrlrange="-2.059 2.0944"/>
    <general name="act3" joint="joint3" class="size2"/>
    <general name="act4" joint="joint4" class="size2" ctrlrange="-0.19198 3.927"/>
    <general name="act5" joint="joint5" class="size2"/>
    <general name="act6" joint="joint6" class="size3" ctrlrange="-1.69297 3.14159"/>
    <general name="act7" joint="joint7" class="size3"/>

    <position name="act_index_q1" joint="index_q1" kp="50" kv="0.5" ctrlrange="0 2.0944" forcerange="-6 6"/>
    <position name="act_index_q2" joint="index_q2" kp="50" kv="0.5" ctrlrange="0 2.6586" forcerange="-6 6"/>
    
    <position name="act_middle_q1" joint="middle_q1" kp="50" kv="0.5" ctrlrange="0 2.0944" forcerange="-6 6"/>
    <position name="act_middle_q2" joint="middle_q2" kp="50" kv="0.5" ctrlrange="0 2.6586" forcerange="-6 6"/>
    
    <position name="act_ring_q1" joint="ring_q1" kp="50" kv="0.5" ctrlrange="0 2.0944" forcerange="-6 6"/>
    <position name="act_ring_q2" joint="ring_q2" kp="50" kv="0.5" ctrlrange="0 2.6586" forcerange="-6 6"/>
    
    <position name="act_pinky_q1" joint="pinky_q1" kp="50" kv="0.5" ctrlrange="0 2.0944" forcerange="-6 6"/>
    <position name="act_pinky_q2" joint="pinky_q2" kp="50" kv="0.5" ctrlrange="0 2.6586" forcerange="-6 6"/>
    
    <position name="act_thumb_q1" joint="thumb_q1" kp="50" kv="0.5" ctrlrange="-2.0944 0" forcerange="-6 6"/>
    <position name="act_thumb_q2" joint="thumb_q2" kp="50" kv="0.5" ctrlrange="0 2.0944" forcerange="-6 6"/>
  </actuator>

  <!-- <keyframe>
    <key name="home" qpos="0 -.247 0 .909 0 1.15644 0" ctrl="0 -.247 0 .909 0 1.15644 0"/>
  </keyframe> -->
</mujoco>
