<mujoco model="xarm7_left_ability_hand">
  <compiler angle="radian" autolimits="true" meshdir="assets"/>

  <option integrator="implicitfast"/>

  <asset>
    <material name="white_left" rgba="1 1 1 1"/>
    <material name="gray_left" rgba="0.753 0.753 0.753 1"/>

    <mesh name="link_base_left" file="link_base.stl"/>
    <mesh name="link1_left" file="link1.stl"/>
    <mesh name="link2_left" file="link2.stl"/>
    <mesh name="link3_left" file="link3.stl"/>
    <mesh name="link4_left" file="link4.stl"/>
    <mesh name="link5_left" file="link5.stl"/>
    <mesh name="link6_left" file="link6.stl"/>
    <mesh name="link7_left" file="link7.stl"/>
    <mesh name="end_tool_left" file="end_tool.stl"/>

    <mesh name="wristmesh_left" file="wristmesh.obj"/>
    <mesh name="wristmesh_C_left" file="wristmesh_C.obj"/>
    <mesh name="FB_palm_ref_left" file="FB_palm_ref.obj"/>
    <mesh name="idx-F1_left" file="idx-F1.obj"/>
    <mesh name="idx-F2_left" file="idx-F2.obj"/>
    <mesh name="idx-F2_C_left" file="idx-F2_C.obj"/>
    <mesh name="thumb-F1_left" file="thumb-F1.obj"/>
    <mesh name="thumb-F1_C_left" file="thumb-F1_C.obj"/>
    <mesh name="thumb-F2_left" file="thumb-F2.obj"/>
    <mesh name="thumb-F2_C_left" file="thumb-F2_C.obj"/>
  </asset>

  <default>
    <default class="xarm7_left">
      <geom type="mesh" material="white_left"/>
      <joint axis="0 0 1" range="-6.28319 6.28319" frictionloss="1"/>
      <general biastype="affine" ctrlrange="-6.28319 6.28319"/>
      <default class="size1_left">
        <joint damping="10"/>
        <general gainprm="1500" biasprm="0 -1500 -150" forcerange="-50 50"/>
      </default>
      <default class="size2_left">
        <joint damping="5"/>
        <general gainprm="1000" biasprm="0 -1000 -100" forcerange="-30 30"/>
      </default>
      <default class="size3_left">
        <joint damping="2"/>
        <general gainprm="800" biasprm="0 -800 -80" forcerange="-20 20"/>
      </default>
      <site size="0.001" rgba="1 0 0 1" group="4"/>
    </default>
  </default>

  <worldbody>
    <body name="link_base_left" pos="-0.3 0.35 0.765" childclass="xarm7_left">
      <inertial pos="-0.021131 -0.0016302 0.056488" quat="0.696843 0.20176 0.10388 0.680376" mass="0.88556"
        diaginertia="0.00382023 0.00335282 0.00167725"/>
      <geom mesh="link_base_left"/>
      <body name="link1_left" pos="0 0 0.267">
        <inertial pos="-0.0002 0.02905 -0.01233" quat="0.978953 -0.202769 -0.00441617 -0.0227264" mass="2.382"
          diaginertia="0.00569127 0.00533384 0.00293865"/>
        <joint name="joint1_left" class="size1_left"/>
        <geom mesh="link1_left"/>
        <body name="link2_left" quat="1 -1 0 0">
          <inertial pos="0.00022 -0.12856 0.01735" quat="0.50198 0.86483 -0.00778841 0.00483285" mass="1.869"
            diaginertia="0.00959898 0.00937717 0.00201315"/>
          <joint name="joint2_left" range="-2.059 2.0944" class="size1_left"/>
          <geom mesh="link2_left"/>
          <body name="link3_left" pos="0 -0.293 0" quat="1 1 0 0">
            <inertial pos="0.0466 -0.02463 -0.00768" quat="0.913819 0.289775 0.281481 -0.0416455" mass="1.6383"
              diaginertia="0.00351721 0.00294089 0.00195868"/>
            <joint name="joint3_left" class="size2_left"/>
            <geom mesh="link3_left"/>
            <body name="link4_left" pos="0.0525 0 0" quat="1 1 0 0">
              <inertial pos="0.07047 -0.11575 0.012" quat="0.422108 0.852026 -0.126025 0.282832" mass="1.7269"
                diaginertia="0.00657137 0.00647948 0.00186763"/>
              <joint name="joint4_left" range="-0.19198 3.927" class="size2_left"/>
              <geom mesh="link4_left"/>
              <body name="link5_left" pos="0.0775 -0.3425 0" quat="1 1 0 0">
                <inertial pos="-0.00032 0.01604 -0.026" quat="0.999311 -0.0304457 0.000577067 0.0212082" mass="1.3203"
                  diaginertia="0.00534729 0.00499076 0.0013489"/>
                <joint name="joint5_left" class="size2_left"/>
                <geom mesh="link5_left"/>
                <body name="link6_left" quat="1 1 0 0">
                  <inertial pos="0.06469 0.03278 0.02141" quat="-0.217672 0.772419 0.16258 0.574069" mass="1.325"
                    diaginertia="0.00245421 0.00221646 0.00107273"/>
                  <joint name="joint6_left" range="-1.69297 3.14159" class="size3_left"/>
                  <geom mesh="link6_left"/>
                  <body name="link7_left" pos="0.076 0.097 0" quat="1 -1 0 0">
                    <inertial pos="0 -0.00677 -0.01098" quat="0.487612 0.512088 -0.512088 0.487612" mass="0.17"
                      diaginertia="0.000132176 9.3e-05 5.85236e-05"/>
                    <joint name="joint7_left" class="size3_left"/>
                    <geom material="gray_left" mesh="end_tool_left"/>
                    <site name="attachment_site_left"/>


                    <geom name="wrist_mesh_left" type="mesh" contype="0" conaffinity="0" group="1" density="0" mesh="wristmesh_left"/>
                    <geom type="mesh" mesh="wristmesh_C_left"/>
                    <geom name="palm_mesh_left" pos="0.0240477 0.00378125 0.0323296" quat="0.0442297 0.00061027 0.999021 2.70192e-05" type="mesh" contype="0" conaffinity="0" group="1" density="0" mesh="FB_palm_ref_left"/>
                    <geom pos="0.0240477 0.00378125 0.0323296" quat="0.0442297 0.00061027 0.999021 2.70192e-05" type="mesh" mesh="FB_palm_ref_left"/>
                    <body name="index_L1_left" pos="0.0279216 -0.00927034 0.0958706" quat="-0.714459 -0.129917 0.685906 0.0469401">
                      <inertial pos="0.0224191 -0.000157982 -1.31987e-05" quat="-0.00406251 0.706621 0.00934715 0.707518" mass="0.00635888" diaginertia="0.000381765 0.000369601 2.96432e-05"/>
                      <joint name="index_q1_left" pos="0 0 0" axis="0 0 1" range="0 2.0944" actuatorfrcrange="-6 6" damping="0.001" frictionloss="0.001"/>
                      <geom name="index_mesh_1_left" pos="0.0384727 0.0032577 0" quat="0.999108 0 0 0.0422244" type="mesh" contype="0" conaffinity="0" group="1" density="0" mesh="idx-F1_left"/>
                      <geom type="sphere" size="0.0085" pos="0.036 -0.00175 0"/>
                      <geom size="0.014 0.006 0.008" pos="0.019 -0.0045 0" quat="0.999108 0 0 0.0422374" type="box"/>
                      <geom size="0.006 0.006 0.001" pos="-0.001 0 0.007" quat="0.999108 0 0 0.0422374" type="box"/>
                      <geom size="0.006 0.006 0.001" pos="-0.001 0 -0.007" quat="0.999108 0 0 0.0422374" type="box"/>
                      <body name="index_L2_left" pos="0.0384727 0.0032577 0" quat="0.999108 0 0 0.0422244">
                        <inertial pos="0.0133682 -0.00875392 -2.886e-05" quat="-0.161363 0.673074 0.216775 0.688434" mass="0.00645" diaginertia="0.000264645 0.000263553 1.71391e-05"/>
                        <joint name="index_q2_left" pos="0 0 0" axis="0 0 1" range="0 2.6586" actuatorfrcrange="-6 6" damping="0.001" frictionloss="0.001"/>
                        <geom name="index_mesh_2_left" pos="0.0091241 0 0" quat="1 0 0 0" type="mesh" contype="0" conaffinity="0" group="1" density="0" mesh="idx-F2_left"/>
                        <geom type="mesh" mesh="idx-F2_C_left"/>
                        <geom type="sphere" size="0.007" pos="0.03 -0.016 0"/>
                      </body>
                    </body>

                    <body name="middle_L1_left" pos="0.00841718 -0.0115172 0.0990634" quat="-0.698395 -0.103508 0.704562 0.0715738">
                      <inertial pos="0.0224191 -0.000157982 -1.31987e-05" quat="-0.00406251 0.706621 0.00934715 0.707518" mass="0.00635888" diaginertia="0.000381765 0.000369601 2.96432e-05"/>
                      <joint name="middle_q1_left" pos="0 0 0" axis="0 0 1" range="0 2.0944" actuatorfrcrange="-6 6" damping="0.001" frictionloss="0.001"/>
                      <geom name="middle_mesh_1_left" pos="0.0384727 0.0032577 0" quat="0.999108 0 0 0.0422244" type="mesh" contype="0" conaffinity="0" group="1" density="0" mesh="idx-F1_left"/>
                      <geom type="sphere" size="0.0085" pos="0.036 -0.00175 0"/>
                      <geom size="0.014 0.006 0.008" pos="0.019 -0.0045 0" quat="0.999108 0 0 0.0422374" type="box"/>
                      <geom size="0.006 0.006 0.001" pos="-0.001 0 0.007" quat="0.999108 0 0 0.0422374" type="box"/>
                      <geom size="0.006 0.006 0.001" pos="-0.001 0 -0.007" quat="0.999108 0 0 0.0422374" type="box"/>
                      <body name="middle_L2_left" pos="0.0384727 0.0032577 0" quat="0.999108 0 0 0.0422244">
                        <inertial pos="0.0133682 -0.00875392 -2.886e-05" quat="-0.161363 0.673074 0.216775 0.688434" mass="0.00645" diaginertia="0.000264645 0.000263553 1.71391e-05"/>
                        <joint name="middle_q2_left" pos="0 0 0" axis="0 0 1" range="0 2.6586" actuatorfrcrange="-6 6" damping="0.001" frictionloss="0.001"/>
                        <geom name="middle_mesh_2_left" pos="0.0091241 0 0" quat="1 0 0 0" type="mesh" contype="0" conaffinity="0" group="1" density="0" mesh="idx-F2_left"/>
                        <geom type="mesh" mesh="idx-F2_C_left"/>
                        <geom type="sphere" size="0.007" pos="0.03 -0.016 0"/>
                      </body>
                    </body>

                    <body name="ring_L1_left" pos="-0.0117529 -0.0103946 0.0967038" quat="-0.681173 -0.0769649 0.721351 0.0986547">
                      <inertial pos="0.0224191 -0.000157982 -1.31987e-05" quat="-0.00406251 0.706621 0.00934715 0.707518" mass="0.00635888" diaginertia="0.000381765 0.000369601 2.96432e-05"/>
                      <joint name="ring_q1_left" pos="0 0 0" axis="0 0 1" range="0 2.0944" actuatorfrcrange="-6 6" damping="0.001" frictionloss="0.001"/>
                      <geom name="ring_mesh_1_left" pos="0.0384727 0.0032577 0" quat="0.999108 0 0 0.0422244" type="mesh" contype="0" conaffinity="0" group="1" density="0" mesh="idx-F1_left"/>
                      <geom type="sphere" size="0.0085" pos="0.036 -0.00175 0"/>
                      <geom size="0.014 0.006 0.008" pos="0.019 -0.0045 0" quat="0.999108 0 0 0.0422374" type="box"/>
                      <geom size="0.006 0.006 0.001" pos="-0.001 0 0.007" quat="0.999108 0 0 0.0422374" type="box"/>
                      <geom size="0.006 0.006 0.001" pos="-0.001 0 -0.007" quat="0.999108 0 0 0.0422374" type="box"/>
                      <body name="ring_L2_left" pos="0.0384727 0.0032577 0" quat="0.999108 0 0 0.0422244">
                        <inertial pos="0.0133682 -0.00875392 -2.886e-05" quat="-0.161363 0.673074 0.216775 0.688434" mass="0.00645" diaginertia="0.000264645 0.000263553 1.71391e-05"/>
                        <joint name="ring_q2_left" pos="0 0 0" axis="0 0 1" range="0 2.6586" actuatorfrcrange="-6 6" damping="0.001" frictionloss="0.001"/>
                        <geom name="ring_mesh_2_left" pos="0.0091241 0 0" quat="1 0 0 0" type="mesh" contype="0" conaffinity="0" group="1" density="0" mesh="idx-F2_left"/>
                        <geom type="mesh" mesh="idx-F2_C_left"/>
                        <geom type="sphere" size="0.007" pos="0.03 -0.016 0"/>
                      </body>
                    </body>

                    <body name="pinky_L1_left" pos="-0.0308633 -0.00716283 0.0907346" quat="-0.681748 -0.0544096 0.719226 0.122363">
                      <inertial pos="0.0224191 -0.000157982 -1.31987e-05" quat="-0.00406251 0.706621 0.00934715 0.707518" mass="0.00635888" diaginertia="0.000381765 0.000369601 2.96432e-05"/>
                      <joint name="pinky_q1_left" pos="0 0 0" axis="0 0 1" range="0 2.0944" actuatorfrcrange="-6 6" damping="0.001" frictionloss="0.001"/>
                      <geom name="pinky_mesh_1_left" pos="0.0384727 0.0032577 0" quat="0.999108 0 0 0.0422244" type="mesh" contype="0" conaffinity="0" group="1" density="0" mesh="idx-F1_left"/>
                      <geom type="sphere" size="0.0085" pos="0.036 -0.00175 0"/>
                      <geom size="0.014 0.006 0.008" pos="0.019 -0.0045 0" quat="0.999108 0 0 0.0422374" type="box"/>
                      <geom size="0.006 0.006 0.001" pos="-0.001 0 0.007" quat="0.999108 0 0 0.0422374" type="box"/>
                      <geom size="0.006 0.006 0.001" pos="-0.001 0 -0.007" quat="0.999108 0 0 0.0422374" type="box"/>
                      <body name="pinky_L2_left" pos="0.0384727 0.0032577 0" quat="0.999108 0 0 0.0422244">
                        <inertial pos="0.0133682 -0.00875392 -2.886e-05" quat="-0.161363 0.673074 0.216775 0.688434" mass="0.00645" diaginertia="0.000264645 0.000263553 1.71391e-05"/>
                        <joint name="pinky_q2_left" pos="0 0 0" axis="0 0 1" range="0 2.6586" actuatorfrcrange="-6 6" damping="0.001" frictionloss="0.001"/>
                        <geom name="pinky_mesh_2_left" pos="0.0091241 0 0" quat="1 0 0 0" type="mesh" contype="0" conaffinity="0" group="1" density="0" mesh="idx-F2_left"/>
                        <geom type="mesh" mesh="idx-F2_C_left"/>
                        <geom type="sphere" size="0.007" pos="0.03 -0.016 0"/>
                      </body>
                    </body>

                    <body name="thumb_L1_left" pos="0.0240477 0.00378125 0.0323296" quat="-0.00419696 0.994514 -0.0947972 0.0440301">
                      <inertial pos="0.014606 -0.00189085 -0.00311554" quat="0.306728 0.531258 0.293089 0.733336" mass="0.00268342" diaginertia="8.14795e-05 7.42718e-05 1.14409e-05"/>
                      <joint name="thumb_q1_left" pos="0 0 0" axis="0 0 1" range="-2.0944 0" actuatorfrcrange="-1.2 1.2" damping="0.001" frictionloss="0.001"/>
                      <geom name="thumb_mesh_1_left" pos="0.0278284 0 -0.0147507" quat="-0.608761 0.793353 0 0" type="mesh" contype="0" conaffinity="0" group="1" density="0" mesh="thumb-F1_left"/>
                      <geom pos="0.0278284 0 -0.0147507" quat="-0.608761 0.793353 0 0" type="mesh" mesh="thumb-F1_C_left"/>
                      <body name="thumb_L2_left" pos="0.0278284 0 -0.0147507" quat="-0.608761 0.793353 0 0">
                        <inertial pos="0.0300205 0.00559476 -0.00415044" quat="0.00721249 0.656735 -0.223684 0.720148" mass="0.0055" diaginertia="0.00180207 0.00170892 0.000287855"/>
                        <joint name="thumb_q2_left" pos="0 0 0" axis="0 0 1" range="0 2.0944" actuatorfrcrange="-6 6" damping="0.001" frictionloss="0.001"/>
                        <geom name="thumb_mesh_2_left" pos="0.0651867 0.0233402 -0.00393483" quat="3.21978e-07 0.985259 0.171069 5.59046e-08" type="mesh" contype="0" conaffinity="0" group="1" density="0" mesh="thumb-F2_left"/>
                        <geom pos="0.0651867 0.0233402 -0.00393483" quat="3.21978e-07 0.985259 0.171069 5.59046e-08" type="mesh" mesh="thumb-F2_C_left"/>
                      </body>
                    </body>


                  </body>
                </body>
              </body>
            </body>
          </body>
        </body>
      </body>
    </body>
  </worldbody>

  <actuator>
    <general name="act1_left" joint="joint1_left" class="size1_left"/>
    <general name="act2_left" joint="joint2_left" class="size1_left" ctrlrange="-2.059 2.0944"/>
    <general name="act3_left" joint="joint3_left" class="size2_left"/>
    <general name="act4_left" joint="joint4_left" class="size2_left" ctrlrange="-0.19198 3.927"/>
    <general name="act5_left" joint="joint5_left" class="size2_left"/>
    <general name="act6_left" joint="joint6_left" class="size3_left" ctrlrange="-1.69297 3.14159"/>
    <general name="act7_left" joint="joint7_left" class="size3_left"/>

    <position name="act_index_q1_left" joint="index_q1_left" kp="50" kv="0.5" ctrlrange="0 2.0944" forcerange="-6 6"/>
    <position name="act_index_q2_left" joint="index_q2_left" kp="50" kv="0.5" ctrlrange="0 2.6586" forcerange="-6 6"/>
    
    <position name="act_middle_q1_left" joint="middle_q1_left" kp="50" kv="0.5" ctrlrange="0 2.0944" forcerange="-6 6"/>
    <position name="act_middle_q2_left" joint="middle_q2_left" kp="50" kv="0.5" ctrlrange="0 2.6586" forcerange="-6 6"/>
    
    <position name="act_ring_q1_left" joint="ring_q1_left" kp="50" kv="0.5" ctrlrange="0 2.0944" forcerange="-6 6"/>
    <position name="act_ring_q2_left" joint="ring_q2_left" kp="50" kv="0.5" ctrlrange="0 2.6586" forcerange="-6 6"/>
    
    <position name="act_pinky_q1_left" joint="pinky_q1_left" kp="50" kv="0.5" ctrlrange="0 2.0944" forcerange="-6 6"/>
    <position name="act_pinky_q2_left" joint="pinky_q2_left" kp="50" kv="0.5" ctrlrange="0 2.6586" forcerange="-6 6"/>
    
    <position name="act_thumb_q1_left" joint="thumb_q1_left" kp="50" kv="0.5" ctrlrange="-2.0944 0" forcerange="-6 6"/>
    <position name="act_thumb_q2_left" joint="thumb_q2_left" kp="50" kv="0.5" ctrlrange="0 2.0944" forcerange="-6 6"/>
  </actuator>
</mujoco>
